
[2024-04-22 11:16:01.544826] - Executing "gerar_erro"...
Traceback (most recent call last):
  File "/usr/lib/python3.8/runpy.py", line 194, in _run_module_as_main
    return _run_code(code, main_globals, None,
  File "/usr/lib/python3.8/runpy.py", line 87, in _run_code
    exec(code, run_globals)
  File "/home/visie/hobbies/crontab-manager/src/scripts/gerar_erro.py", line 13, in <module>
    main()
  File "/home/visie/hobbies/crontab-manager/src/scripts/gerar_erro.py", line 8, in main
    print(1/0)
ZeroDivisionError: division by zero
